Workbook

Sheet Read me
A1: NESR SCMS configuration register
A2: Team 3. Satellite communication and observation along the sea route in all weather conditions with monitoring of ice conditions.
A3: Repository: https://github.com/VladZg/NESR
A5: Configuration manager
A6: Jash Joshi (proposed). Backup for model and requirements files: Vladislav Zagorodnyuk.
A8: Sheets
A9: CI register: every configuration item (CI): owner, version, status, PDR deliverable, path in the repository.
A10: PDR checklist: the 9 PDR deliverables of the course, their primary CI and progress of all CIs that belong to each.
A11: By member: CIs per team member and their status.
A12: Folders: repository folders and number of CIs in each.
A13: Baselines: planned baselines and git tags.
A14: Change log: one row per new version of a CI.
... A22: Yellow cells are edited by CI owners and the configuration manager; grey cells are formulas.

Sheet CI register
A1: CI ID | B1: Title | C1: Category | D1: Owner | E1: Formats | F1: Version | G1: Status | H1: PDR item | I1: Path in repository | J1: In repo | K1: Last update | L1: Notes
A2: MGT-001 | B2: Configuration register | C2: MGT | D2: Jash Joshi | E2: xlsx | F2: v0.2 | G2: Draft | H2: 8 | I2: 08_Configuration_Data_Management/T3_MGT-001_Configuration-Register.xlsx | J2: Yes | K2: 46324 | L2: Single source of truth for all CIs
A3: MGT-002 | B3: Product card (repository README.md) | C3: MGT | D3: Jash Joshi | E3: md | F3: v0.1 | G3: Draft | I3: README.md | J3: Yes | K3: 46324 | L3: Stored as README.md
A4: MGT-003 | B4: Project management plan | C4: MGT | D4: Jash Joshi | E4: md | F4: v0.1 | G4: Draft | H4: 4 | I4: 04_Project_Management/T3_MGT-003_Project-Management-Plan.md | J4: Yes | K4: 46324 | L4: Starter text, to complete
A5: MGT-004 | B5: Team roles and responsibilities | C5: MGT | D5: Jash Joshi | E5: md | F5: v0.1 | G5: Draft | H5: 4 | I5: 04_Project_Management/T3_MGT-004_Team-Roles.md | J5: Yes | K5: 46324 | L5: Inside the project management plan
A6: MGT-005 | B6: Schedule and milestones | C6: MGT | D6: Jash Joshi | E6: md | F6: - | G6: Planned | H6: 4 | I6: 04_Project_Management/T3_MGT-005_Schedule-and-Milestones.md | J6: No | L6: Dates of SRR and PDR to add
A7: MGT-006 | B7: Work breakdown structure | C7: MGT | D7: Jash Joshi | E7: csv | F7: v0.1 | G7: Draft | H7: 4 | I7: 04_Project_Management/T3_MGT-006_WBS.csv | J7: Yes | K7: 46324
A8: MGT-007 | B8: Configuration and data management baseline plan | C8: MGT | D8: Jash Joshi | E8: md | F8: v0.1 | G8: Draft | H8: 8 | I8: 08_Configuration_Data_Management/T3_MGT-007_CM-DM-Baseline-Plan.md | J8: Yes | K8: 46324
A9: MGT-008 | B9: Naming, versioning and review rules (CONTRIBUTING.md) | C9: MGT | D9: Jash Joshi | E9: md | F9: v0.1 | G9: Draft | H9: 8 | I9: CONTRIBUTING.md | J9: Yes | K9: 46324 | L9: Stored as CONTRIBUTING.md
A10: REQ-001 | B10: Mission statement, needs, goals, objectives and MOEs | C10: REQ | D10: Jash Joshi | E10: md | F10: v0.1 | G10: Draft | H10: 2 | I10: 03_Requirements/T3_REQ-001_Mission-Statement-and-NGO.md | J10: Yes | K10: 46324
A11: REQ-002 | B11: Stakeholder register | C11: REQ | D11: Jash Joshi | E11: md | F11: v0.1 | G11: Draft | H11: 1 | I11: 03_Requirements/T3_REQ-002_Stakeholder-Register.md | J11: Yes | K11: 46324 | L11: Also a sheet in REQ-003
A12: REQ-003 | B12: System (SR) and technical (TR) requirements with traceability | C12: REQ | D12: Vladislav Zagorodnyuk | E12: xlsx, md | F12: v0.3 | G12: Draft | H12: 3 | I12: 03_Requirements/T3_REQ-003_System-and-Technical-Requirements.xlsx 03_Requirements/T3_REQ-003_System-and-Technical-Requirements.md | J12: Yes | K12: 46324 | L12: 11 SR, 32 TR
A13: REQ-004 | B13: Similar missions review and RADARSAT requirements analysis | C13: REQ | D13: Vladislav Zagorodnyuk | E13: md | F13: - | G13: Planned | I13: references/T3_REQ-004_Reference-Missions-Review.md | J13: No
A14: REQ-005 | B14: Compliance check with maritime regulations | C14: REQ | D14: Mikhail Timofeenko | E14: csv | F14: v0.1 | G14: Draft | H14: 9 | I14: 09_Maritime_Compliance/T3_REQ-005_Maritime-Compliance-Matrix.csv | J14: Yes | K14: 46324 | L14: Starter matrix, statuses to confirm
A15: CON-001 | B15: Concept of operations | C15: CON | D15: Jash Joshi | E15: md | F15: v0.1 | G15: Draft | H15: 2 | I15: 02_ConOps/T3_CON-001_ConOps.md | J15: Yes | K15: 46324 | L15: Starter text with scenarios S1 to S6
A16: CON-002 | B16: Scenario map: functional chains S1 to S6 | C16: CON | D16: Vladislav Zagorodnyuk | E16: svg, png | F16: v0.1 | G16: Draft | H16: 2 | I16: 02_ConOps/T3_CON-002_Scenario-Map.svg 02_ConOps/T3_CON-002_Scenario-Map.png | J16: Yes | K16: 46321
A17: ARC-001 | B17: IDEF0 A-0 context diagram | C17: ARC | D17: Victoria Kulikova | E17: svg, png | F17: v0.1 | G17: Draft | H17: 1 | I17: 01_MBSE_Model/functional_analysis/T3_ARC-001_IDEF0-A-0-Context.svg 01_MBSE_Model/functional_analysis/T3_ARC-001_IDEF0-A-0-Context.png | J17: Yes | K17: 46322
A18: ARC-002 | B18: IDEF0 A0 decomposition | C18: ARC | D18: Victoria Kulikova | E18: svg, png | F18: v0.1 | G18: Draft | H18: 1 | I18: 01_MBSE_Model/functional_analysis/T3_ARC-002_IDEF0-A0-Decomposition.svg 01_MBSE_Model/functional_analysis/T3_ARC-002_IDEF0-A0-Decomposition.png | J18: Yes | K18: 46317
A19: ARC-003 | B19: IDEF0 A4 Deliver commands to ships | C19: ARC | D19: Vladislav Zagorodnyuk | E19: svg, png | F19: v0.1 | G19: Draft | H19: 1 | I19: 01_MBSE_Model/functional_analysis/T3_ARC-003_IDEF0-A4-Deliver-Commands.svg 01_MBSE_Model/functional_analysis/T3_ARC-003_IDEF0-A4-Deliver-Commands.png | J19: Yes | K19: 46321
A20: ARC-005 | B20: N2 diagram of system interfaces | C20: ARC | D20: Victoria Kulikova | E20: png | F20: - | G20: Planned | H20: 7 | I20: 07_Interface_Management/T3_ARC-005_N2-Diagram.png | J20: No
A21: ARC-006 | B21: Interface control documents ICD-01 to ICD-06 | C21: ARC | D21: Victoria Kulikova | E21: md | F21: - | G21: Planned | H21: 7 | I21: 07_Interface_Management/T3_ARC-006_ICD-List.md | J21: No | L21: Listed in ARC-009
A22: ARC-009 | B22: Interface management plan | C22: ARC | D22: Victoria Kulikova | E22: md | F22: v0.1 | G22: Draft | H22: 7 | I22: 07_Interface_Management/T3_ARC-009_Interface-Management-Plan.md | J22: Yes | K22: 46324 | L22: Starter text with interface list
A23: MOD-001 | B23: Capella project NESR SCMS (.capella, .aird) as zip | C23: MOD | D23: Vladislav Zagorodnyuk | E23: zip | F23: v0.1 | G23: Draft | H23: 1 | I23: 01_MBSE_Model/capella/T3_MOD-001_Capella-Model.zip | J23: No | L23: To upload; fix typo 'montoring' in model name
A24: MOD-002 | B24: OAB Operational Architecture Blank | C24: MOD | D24: Vladislav Zagorodnyuk | E24: png | F24: v0.1 | G24: Draft | H24: 1 | I24: 01_MBSE_Model/diagrams/1_Operational_Analysis/T3_MOD-002_OAB-Operational-Architecture.png | J24: Yes | K24: 46314
A25: MOD-003 | B25: OEBD Operational Entity Breakdown | C25: MOD | D25: Vladislav Zagorodnyuk | E25: png | F25: v0.1 | G25: Draft | H25: 1 | I25: 01_MBSE_Model/diagrams/1_Operational_Analysis/T3_MOD-003_OEBD-Operational-Entities.png | J25: Yes | K25: 46314 | L25: GLONASS is MEO, not GSO: fix label
A26: MOD-004 | B26: OCB Operational Capabilities Blank | C26: MOD | D26: Vladislav Zagorodnyuk | E26: png | F26: v0.1 | G26: Draft | H26: 1 | I26: 01_MBSE_Model/diagrams/1_Operational_Analysis/T3_MOD-004_OCB-Operational-Capabilities.png | J26: Yes | K26: 46314
A27: MOD-005 | B27: CSA Contextual System Actors | C27: MOD | D27: Vladislav Zagorodnyuk | E27: png | F27: v0.1 | G27: Draft | H27: 1 | I27: 01_MBSE_Model/diagrams/2_System_Analysis/T3_MOD-005_CSA-Contextual-System-Actors.png | J27: Yes | K27: 46322
A28: MOD-006 | B28: SDFB with functional chains S1, S3a, S3b, S6 | C28: MOD | D28: Vladislav Zagorodnyuk | E28: svg | F28: v0.1 | G28: Draft | H28: 1 | I28: 01_MBSE_Model/diagrams/2_System_Analysis/T3_MOD-006_SDFB-Root-System-Function.svg | J28: Yes | K28: 46322
A29: MOD-007 | B29: SAB System Architecture Blank | C29: MOD | D29: Vladislav Zagorodnyuk | E29: png | F29: v0.1 | G29: Draft | H29: 1 | I29: 01_MBSE_Model/diagrams/2_System_Analysis/T3_MOD-007_SAB-System-Architecture.png | J29: Yes | K29: 46322
A30: MOD-008 | B30: System Analysis diagrams package (CSA, SDFB, SAB) | C30: MOD | D30: Vladislav Zagorodnyuk | E30: pdf | F30: v0.1 | G30: Draft | H30: 1 | I30: 01_MBSE_Model/diagrams/2_System_Analysis/T3_MOD-008_System-Analysis-Diagrams.pdf | J30: Yes | K30: 46322 | L30: Submitted for problem set 2
A31: MOD-009 | B31: Exchange scenarios (ES) for S2 and S6 | C31: MOD | D31: Vladislav Zagorodnyuk | E31: png | F31: - | G31: Planned | H31: 1 | I31: 01_MBSE_Model/diagrams/2_System_Analysis/T3_MOD-009_ES-Exchange-Scenarios.png | J31: No
A32: MOD-010 | B32: Logical architecture (LAB, LFBD) in Capella | C32: MOD | D32: Victoria Kulikova | E32: png | F32: - | G32: Planned | H32: 1 | I32: 01_MBSE_Model/diagrams/3_Logical_Architecture/T3_MOD-010_LAB-Logical-Architecture.png | J32: No | L32: Required by PDR item 1
A33: SIM-001 | B33: Kondor-FKA coverage and revisit over the NSR | C33: SIM | D33: Vladislav Zagorodnyuk | E33: py | F33: - | G33: Planned | H33: 3 | I33: analysis/T3_SIM-001_SAR-Coverage-and-Revisit.py | J33: No | L33: Confirms TR-13 (24 h TBR)
A34: SIM-002 | B34: Communication coverage and availability, 66 to 82 deg N | C34: SIM | D34: Vladislav Zagorodnyuk | E34: py | F34: - | G34: Planned | H34: 3 | I34: analysis/T3_SIM-002_Comms-Availability.py | J34: No | L34: Verifies TR-09
A35: SIM-003 | B35: End-to-end latency budget | C35: SIM | D35: Vladislav Zagorodnyuk | E35: xlsx | F35: - | G35: Planned | H35: 3 | I35: analysis/T3_SIM-003_Latency-Budget.xlsx | J35: No | L35: Verifies TR-10, TR-11, TR-14
A36: SIM-004 | B36: Trade study: LEO vs HEO communication architecture | C36: SIM | D36: Vladislav Zagorodnyuk | E36: xlsx | F36: - | G36: Planned | I36: analysis/T3_SIM-004_Trade-Study-LEO-vs-HEO.xlsx | J36: No
A37: SAF-001 | B37: Risk register (5x5) | C37: SAF | D37: Mikhail Timofeenko | E37: csv | F37: v0.1 | G37: Draft | H37: 5 | I37: 05_Risk_Analysis/T3_SAF-001_Risk-Register.csv | J37: Yes | K37: 46324 | L37: Seeded with 7 risks
A38: SAF-002 | B38: FMEA: on-board terminal and ground platform | C38: SAF | D38: Mikhail Timofeenko | E38: xlsx | F38: - | G38: Planned | H38: 5 | I38: 05_Risk_Analysis/T3_SAF-002_FMEA.xlsx | J38: No
A39: SAF-003 | B39: Reliability and availability analysis | C39: SAF | D39: Mikhail Timofeenko | E39: xlsx | F39: - | G39: Planned | H39: 5 | I39: 05_Risk_Analysis/T3_SAF-003_Reliability-and-Availability.xlsx | J39: No | L39: Verifies TR-23, TR-24
A40: VV-001 | B40: Verification cross-reference matrix | C40: VV | D40: Mikhail Timofeenko | E40: csv | F40: v0.1 | G40: Draft | H40: 6 | I40: 06_Verification_Validation/T3_VV-001_VCRM.csv | J40: Yes | K40: 46324 | L40: Generated from REQ-003
...

Sheet PDR checklist
A1: # | B1: PDR deliverable | C1: Folder | D1: Owner | E1: Primary CI | F1: Primary CI status | G1: CIs | H1: Planned | I1: Draft or in review | J1: Baselined | K1: Progress
A2: 1 | B2: MBSE model in Arcadia-Capella: stakeholders, operational analysis, system analysis, logical architecture | C2: 01_MBSE_Model | D2: Vladislav Zagorodnyuk | E2: MOD-001 | F2: =INDEX('CI register'!$G$2:$G$44,MATCH($E2,'CI register'!$A$2:$A$44,0)) -> Draft | G2: =COUNTIF('CI register'!$H$2:$H$44,$A2) -> 14 | H2: =COUNTIFS('CI register'!$H$2:$H$44,$A2,'CI register'!$G$2:$G$44,"Planned") -> 2 | I2: =COUNTIFS('CI register'!$H$2:$H$44,$A2,'CI register'!$G$2:$G$44,"Draft")+COUNTIFS('CI register'!$H$2:$H$44,$A2,'CI register'!$G$2:$G$44,"In review") -> 12 | J2: =COUNTIFS('CI register'!$H$2:$H$44,$A2,'CI register'!$G$2:$G$44,"Baselined") -> 0 | K2: =IF(G2=0,0,(I2*0.5+J2)/G2) -> 0.42857143
A3: 2 | B3: ConOps of the proposed system | C3: 02_ConOps | D3: Jash Joshi | E3: CON-001 | F3: =INDEX('CI register'!$G$2:$G$44,MATCH($E3,'CI register'!$A$2:$A$44,0)) -> Draft | G3: =COUNTIF('CI register'!$H$2:$H$44,$A3) -> 3 | H3: =COUNTIFS('CI register'!$H$2:$H$44,$A3,'CI register'!$G$2:$G$44,"Planned") -> 0 | I3: =COUNTIFS('CI register'!$H$2:$H$44,$A3,'CI register'!$G$2:$G$44,"Draft")+COUNTIFS('CI register'!$H$2:$H$44,$A3,'CI register'!$G$2:$G$44,"In review") -> 3 | J3: =COUNTIFS('CI register'!$H$2:$H$44,$A3,'CI register'!$G$2:$G$44,"Baselined") -> 0 | K3: =IF(G3=0,0,(I3*0.5+J3)/G3) -> 0.5
A4: 3 | B4: Clear set of technical requirements | C4: 03_Requirements | D4: Vladislav Zagorodnyuk | E4: REQ-003 | F4: =INDEX('CI register'!$G$2:$G$44,MATCH($E4,'CI register'!$A$2:$A$44,0)) -> Draft | G4: =COUNTIF('CI register'!$H$2:$H$44,$A4) -> 4 | H4: =COUNTIFS('CI register'!$H$2:$H$44,$A4,'CI register'!$G$2:$G$44,"Planned") -> 3 | I4: =COUNTIFS('CI register'!$H$2:$H$44,$A4,'CI register'!$G$2:$G$44,"Draft")+COUNTIFS('CI register'!$H$2:$H$44,$A4,'CI register'!$G$2:$G$44,"In review") -> 1 | J4: =COUNTIFS('CI register'!$H$2:$H$44,$A4,'CI register'!$G$2:$G$44,"Baselined") -> 0 | K4: =IF(G4=0,0,(I4*0.5+J4)/G4) -> 0.125
A5: 4 | B5: Project management plan including WBS | C5: 04_Project_Management | D5: Jash Joshi | E5: MGT-003 | F5: =INDEX('CI register'!$G$2:$G$44,MATCH($E5,'CI register'!$A$2:$A$44,0)) -> Draft | G5: =COUNTIF('CI register'!$H$2:$H$44,$A5) -> 4 | H5: =COUNTIFS('CI register'!$H$2:$H$44,$A5,'CI register'!$G$2:$G$44,"Planned") -> 1 | I5: =COUNTIFS('CI register'!$H$2:$H$44,$A5,'CI register'!$G$2:$G$44,"Draft")+COUNTIFS('CI register'!$H$2:$H$44,$A5,'CI register'!$G$2:$G$44,"In review") -> 3 | J5: =COUNTIFS('CI register'!$H$2:$H$44,$A5,'CI register'!$G$2:$G$44,"Baselined") -> 0 | K5: =IF(G5=0,0,(I5*0.5+J5)/G5) -> 0.375
A6: 5 | B6: Risk analysis | C6: 05_Risk_Analysis | D6: Mikhail Timofeenko | E6: SAF-001 | F6: =INDEX('CI register'!$G$2:$G$44,MATCH($E6,'CI register'!$A$2:$A$44,0)) -> Draft | G6: =COUNTIF('CI register'!$H$2:$H$44,$A6) -> 3 | H6: =COUNTIFS('CI register'!$H$2:$H$44,$A6,'CI register'!$G$2:$G$44,"Planned") -> 2 | I6: =COUNTIFS('CI register'!$H$2:$H$44,$A6,'CI register'!$G$2:$G$44,"Draft")+COUNTIFS('CI register'!$H$2:$H$44,$A6,'CI register'!$G$2:$G$44,"In review") -> 1 | J6: =COUNTIFS('CI register'!$H$2:$H$44,$A6,'CI register'!$G$2:$G$44,"Baselined") -> 0 | K6: =IF(G6=0,0,(I6*0.5+J6)/G6) -> 0.16666667
A7: 6 | B7: System verification and validation plans | C7: 06_Verification_Validation | D7: Mikhail Timofeenko | E7: VV-002 | F7: =INDEX('CI register'!$G$2:$G$44,MATCH($E7,'CI register'!$A$2:$A$44,0)) -> Draft | G7: =COUNTIF('CI register'!$H$2:$H$44,$A7) -> 2 | H7: =COUNTIFS('CI register'!$H$2:$H$44,$A7,'CI register'!$G$2:$G$44,"Planned") -> 0 | I7: =COUNTIFS('CI register'!$H$2:$H$44,$A7,'CI register'!$G$2:$G$44,"Draft")+COUNTIFS('CI register'!$H$2:$H$44,$A7,'CI register'!$G$2:$G$44,"In review") -> 2 | J7: =COUNTIFS('CI register'!$H$2:$H$44,$A7,'CI register'!$G$2:$G$44,"Baselined") -> 0 | K7: =IF(G7=0,0,(I7*0.5+J7)/G7) -> 0.5
A8: 7 | B8: Interface management plan | C8: 07_Interface_Management | D8: Victoria Kulikova | E8: ARC-009 | F8: =INDEX('CI register'!$G$2:$G$44,MATCH($E8,'CI register'!$A$2:$A$44,0)) -> Draft | G8: =COUNTIF('CI register'!$H$2:$H$44,$A8) -> 3 | H8: =COUNTIFS('CI register'!$H$2:$H$44,$A8,'CI register'!$G$2:$G$44,"Planned") -> 2 | I8: =COUNTIFS('CI register'!$H$2:$H$44,$A8,'CI register'!$G$2:$G$44,"Draft")+COUNTIFS('CI register'!$H$2:$H$44,$A8,'CI register'!$G$2:$G$44,"In review") -> 1 | J8: =COUNTIFS('CI register'!$H$2:$H$44,$A8,'CI register'!$G$2:$G$44,"Baselined") -> 0 | K8: =IF(G8=0,0,(I8*0.5+J8)/G8) -> 0.16666667
A9: 8 | B9: Configuration management and data management baseline plan | C9: 08_Configuration_Data_Management | D9: Jash Joshi | E9: MGT-007 | F9: =INDEX('CI register'!$G$2:$G$44,MATCH($E9,'CI register'!$A$2:$A$44,0)) -> Draft | G9: =COUNTIF('CI register'!$H$2:$H$44,$A9) -> 3 | H9: =COUNTIFS('CI register'!$H$2:$H$44,$A9,'CI register'!$G$2:$G$44,"Planned") -> 0 | I9: =COUNTIFS('CI register'!$H$2:$H$44,$A9,'CI register'!$G$2:$G$44,"Draft")+COUNTIFS('CI register'!$H$2:$H$44,$A9,'CI register'!$G$2:$G$44,"In review") -> 3 | J9: =COUNTIFS('CI register'!$H$2:$H$44,$A9,'CI register'!$G$2:$G$44,"Baselined") -> 0 | K9: =IF(G9=0,0,(I9*0.5+J9)/G9) -> 0.5
A10: 9 | B10: Compliance check with maritime regulations | C10: 09_Maritime_Compliance | D10: Mikhail Timofeenko | E10: REQ-005 | F10: =INDEX('CI register'!$G$2:$G$44,MATCH($E10,'CI register'!$A$2:$A$44,0)) -> Draft | G10: =COUNTIF('CI register'!$H$2:$H$44,$A10) -> 1 | H10: =COUNTIFS('CI register'!$H$2:$H$44,$A10,'CI register'!$G$2:$G$44,"Planned") -> 0 | I10: =COUNTIFS('CI register'!$H$2:$H$44,$A10,'CI register'!$G$2:$G$44,"Draft")+COUNTIFS('CI register'!$H$2:$H$44,$A10,'CI register'!$G$2:$G$44,"In review") -> 1 | J10: =COUNTIFS('CI register'!$H$2:$H$44,$A10,'CI register'!$G$2:$G$44,"Baselined") -> 0 | K10: =IF(G10=0,0,(I10*0.5+J10)/G10) -> 0.5
B11: Total | G11: =SUM(G2:G10) -> 37 | H11: =SUM(H2:H10) -> 10 | I11: =SUM(I2:I10) -> 27 | J11: =SUM(J2:J10) -> 0 | K11: =IF(G11=0,0,(I11*0.5+J11)/G11) -> 0.36486486
B13: Progress counts a draft as half done and a baselined item as done.

Sheet By member
A1: Team member | B1: Role | C1: Responsible for | D1: CIs owned | E1: Planned | F1: Draft | G1: In review | H1: Baselined
A2: Vladislav Zagorodnyuk | B2: MBSE and Requirements Engineer | C2: Capella model (OA, SA) and diagrams; system and technical requirements; IDEF0 A4; simulations | D2: =COUNTIF('CI register'!$D$2:$D$44,$A2) -> 18 | E2: =COUNTIFS('CI register'!$D$2:$D$44,$A2,'CI register'!$G$2:$G$44,"Planned") -> 6 | F2: =COUNTIFS('CI register'!$D$2:$D$44,$A2,'CI register'!$G$2:$G$44,"Draft") -> 12 | G2: =COUNTIFS('CI register'!$D$2:$D$44,$A2,'CI register'!$G$2:$G$44,"In review") -> 0 | H2: =COUNTIFS('CI register'!$D$2:$D$44,$A2,'CI register'!$G$2:$G$44,"Baselined") -> 0
A3: Victoria Kulikova | B3: Functional & Interface Engineer and Architecture | C3: IDEF0 A-0 and A0; logical architecture; N2; ICDs; interface management plan | D3: =COUNTIF('CI register'!$D$2:$D$44,$A3) -> 6 | E3: =COUNTIFS('CI register'!$D$2:$D$44,$A3,'CI register'!$G$2:$G$44,"Planned") -> 3 | F3: =COUNTIFS('CI register'!$D$2:$D$44,$A3,'CI register'!$G$2:$G$44,"Draft") -> 3 | G3: =COUNTIFS('CI register'!$D$2:$D$44,$A3,'CI register'!$G$2:$G$44,"In review") -> 0 | H3: =COUNTIFS('CI register'!$D$2:$D$44,$A3,'CI register'!$G$2:$G$44,"Baselined") -> 0
A4: Jash Joshi | B4: Stakeholders and Documentation Engineer, configuration manager (proposed) | C4: Mission and NGO; stakeholders; ConOps; project management plan and WBS; CM/DM plan | D4: =COUNTIF('CI register'!$D$2:$D$44,$A4) -> 12 | E4: =COUNTIFS('CI register'!$D$2:$D$44,$A4,'CI register'!$G$2:$G$44,"Planned") -> 1 | F4: =COUNTIFS('CI register'!$D$2:$D$44,$A4,'CI register'!$G$2:$G$44,"Draft") -> 11 | G4: =COUNTIFS('CI register'!$D$2:$D$44,$A4,'CI register'!$G$2:$G$44,"In review") -> 0 | H4: =COUNTIFS('CI register'!$D$2:$D$44,$A4,'CI register'!$G$2:$G$44,"Baselined") -> 0
A5: Mikhail Timofeenko | B5: Safety, Risk, Reliability, Verification and Validation Engineer | C5: Risk analysis; FMEA; reliability; V&V plans; maritime compliance check | D5: =COUNTIF('CI register'!$D$2:$D$44,$A5) -> 6 | E5: =COUNTIFS('CI register'!$D$2:$D$44,$A5,'CI register'!$G$2:$G$44,"Planned") -> 2 | F5: =COUNTIFS('CI register'!$D$2:$D$44,$A5,'CI register'!$G$2:$G$44,"Draft") -> 4 | G5: =COUNTIFS('CI register'!$D$2:$D$44,$A5,'CI register'!$G$2:$G$44,"In review") -> 0 | H5: =COUNTIFS('CI register'!$D$2:$D$44,$A5,'CI register'!$G$2:$G$44,"Baselined") -> 0
A6: All (CM assembles) | B6: Whole team | C6: Review packages: PDR presentation | D6: =COUNTIF('CI register'!$D$2:$D$44,$A6) -> 1 | E6: =COUNTIFS('CI register'!$D$2:$D$44,$A6,'CI register'!$G$2:$G$44,"Planned") -> 1 | F6: =COUNTIFS('CI register'!$D$2:$D$44,$A6,'CI register'!$G$2:$G$44,"Draft") -> 0 | G6: =COUNTIFS('CI register'!$D$2:$D$44,$A6,'CI register'!$G$2:$G$44,"In review") -> 0 | H6: =COUNTIFS('CI register'!$D$2:$D$44,$A6,'CI register'!$G$2:$G$44,"Baselined") -> 0
A7: Total | D7: =SUM(D2:D6) -> 43 | E7: =SUM(E2:E6) -> 13 | F7: =SUM(F2:F6) -> 30 | G7: =SUM(G2:G6) -> 0 | H7: =SUM(H2:H6) -> 0

Sheet Folders
A1: Folder | B1: PDR item | C1: CIs
A2: 01_MBSE_Model/capella | B2: 1 | C2: =COUNTIF('CI register'!$I$2:$I$44,$A2&"/*") -> 1
A3: 01_MBSE_Model/diagrams/1_Operational_Analysis | B3: 1 | C3: =COUNTIF('CI register'!$I$2:$I$44,$A3&"/*") -> 3
A4: 01_MBSE_Model/diagrams/2_System_Analysis | B4: 1 | C4: =COUNTIF('CI register'!$I$2:$I$44,$A4&"/*") -> 5
A5: 01_MBSE_Model/diagrams/3_Logical_Architecture | B5: 1 | C5: =COUNTIF('CI register'!$I$2:$I$44,$A5&"/*") -> 1
A6: 01_MBSE_Model/functional_analysis | B6: 1 | C6: =COUNTIF('CI register'!$I$2:$I$44,$A6&"/*") -> 3
A7: 02_ConOps | B7: 2 | C7: =COUNTIF('CI register'!$I$2:$I$44,$A7&"/*") -> 2
A8: 03_Requirements | B8: 3 | C8: =COUNTIF('CI register'!$I$2:$I$44,$A8&"/*") -> 3
A9: 04_Project_Management | B9: 4 | C9: =COUNTIF('CI register'!$I$2:$I$44,$A9&"/*") -> 4
A10: 05_Risk_Analysis | B10: 5 | C10: =COUNTIF('CI register'!$I$2:$I$44,$A10&"/*") -> 3
A11: 06_Verification_Validation | B11: 6 | C11: =COUNTIF('CI register'!$I$2:$I$44,$A11&"/*") -> 2
A12: 07_Interface_Management | B12: 7 | C12: =COUNTIF('CI register'!$I$2:$I$44,$A12&"/*") -> 3
A13: 08_Configuration_Data_Management | B13: 8 | C13: =COUNTIF('CI register'!$I$2:$I$44,$A13&"/*") -> 2
A14: 09_Maritime_Compliance | B14: 9 | C14: =COUNTIF('CI register'!$I$2:$I$44,$A14&"/*") -> 1
A15: analysis | C15: =COUNTIF('CI register'!$I$2:$I$44,$A15&"/*") -> 4
A16: problem-sets/PS02_System_Analysis | C16: =COUNTIF('CI register'!$I$2:$I$44,$A16&"/*") -> 1
A17: references | C17: =COUNTIF('CI register'!$I$2:$I$44,$A17&"/*") -> 2
A18: reviews | C18: =COUNTIF('CI register'!$I$2:$I$44,$A18&"/*") -> 1
A19: . | C19: =COUNTIF('CI register'!$I$2:$I$44,"README.md")+COUNTIF('CI register'!$I$2:$I$44,"CONTRIBUTING.md") -> 2

Sheet Baselines
A1: Baseline | B1: Review | C1: Content | D1: Git tag | E1: Date | F1: Status
A2: Functional | B2: SRR | C2: Mission and NGO, stakeholders, system requirements, ConOps | D2: srr-baseline | F2: Planned
A3: Allocated | B3: PDR | C3: All 9 PDR deliverables at v1.0 | D3: pdr-v1.0 | F3: Planned
A4: Product | B4: CDR | C4: Detailed design (later phase) | D4: cdr-v2.0 | F4: Planned

Sheet Change log
A1: Date | B1: CI ID | C1: From version | D1: To version | E1: Change | F1: Author | G1: Issue / PR
A2: 46324 | B2: MGT-001 | C2: v0.1 | D2: v0.2 | E2: Register moved to the GitHub repository; file names without versions; official 9 PDR deliverables | F2: Jash Joshi | G2: initial commit
A3: 46324 | B3: REQ-003 | C3: v0.2 | D3: v0.3 | E3: Reduced to 11 SR and 32 TR with concrete values | F3: Vladislav Zagorodnyuk | G3: initial commit
